# Validator Error Analysis: DNS Resolution Failure

## Error Summary
The validator is failing with DNS resolution errors when trying to access the S3 authentication service:

```
HTTPSConnectionPool (host='sn46-s3-auth.resilabs.ai', port=443): Max retries exceeded with url: /get-folder-presigned-urls
NameResolutionError: Failed to resolve 'sn46-s3-auth.resilabs.ai' ([Errno -2] Name or service not known)
```

## Root Cause Analysis

### 1. **Configuration Mismatch** ‚ùå
The validator is configured for **Subnet 46 (mainnet)** but using the **wrong S3 auth URL**:

- **Current Configuration**: `https://sn46-s3-auth.resilabs.ai` (from `neurons/config.py:125`)
- **Expected for Subnet 46**: `https://s3-auth-api.resilabs.ai` (mainnet)
- **Expected for Subnet 428**: `https://s3-auth-api-testnet.resilabs.ai` (testnet)

### 2. **Environment Configuration** ‚úÖ
The `.env` file shows the validator is running on **testnet (Subnet 428)**:
- `NETUID=428`
- `SUBTENSOR_NETWORK=test`

### 3. **S3 URL Auto-Configuration Logic** üîç
The miner has auto-configuration logic that works correctly:
```python
# In neurons/miner.py:76-84
if self.config.netuid == 428:  # Testnet
    if self.config.s3_auth_url == "https://sn46-s3-auth.resilabs.ai":  # Default mainnet URL
        self.config.s3_auth_url = "https://s3-auth-api-testnet.resilabs.ai"
```

**However, the validator does NOT have this auto-configuration logic!**

### 4. **DNS Resolution Issue** ‚ùå
The hostname `sn46-s3-auth.resilabs.ai` appears to be:
- **Non-existent** or **not publicly accessible**
- **Not resolving** to any IP address
- **Different from the working URLs** used elsewhere in the codebase

## Evidence from Codebase

### Working S3 URLs (Found in codebase):
- `https://s3-auth-api-testnet.resilabs.ai` (testnet - 27 references)
- `https://s3-auth-api.resilabs.ai` (mainnet - 27 references)

### Problematic URL (Only in config default):
- `https://sn46-s3-auth.resilabs.ai` (only 4 references, all in config defaults)

## Impact on Validation Process

1. **S3 Validation Fails**: Validators cannot access miner S3 data
2. **Miner Scoring Affected**: S3 validation contributes to miner scores
3. **Network Health**: Validators cannot properly evaluate miners
4. **Error Cascade**: 
   - `_get_miner_job_folders()` fails
   - S3 validation returns 0.0% score
   - Miners get marked as "S3 Invalid"

## Solutions

### Option 1: Fix Validator Auto-Configuration (Recommended)
Add the same auto-configuration logic to the validator that exists in the miner:

```python
# In neurons/validator.py __init__ method
if self.config.netuid == 428:  # Testnet
    if self.config.s3_auth_url == "https://sn46-s3-auth.resilabs.ai":
        self.config.s3_auth_url = "https://s3-auth-api-testnet.resilabs.ai"
        bt.logging.info(f"Auto-configured testnet S3 auth URL: {self.config.s3_auth_url}")
```

### Option 2: Override via Command Line
Run validator with explicit S3 URL:
```bash
python neurons/validator.py --s3_auth_url https://s3-auth-api-testnet.resilabs.ai --netuid 428
```

### Option 3: Update Environment File
Add to `.env`:
```
S3_AUTH_URL=https://s3-auth-api-testnet.resilabs.ai
```

## Additional Issues Found

### 1. **Miner Connection Failures**
```
ClientConnectorError: Cannot connect to host 0.0.0.0:0 ssl:default [Connect call failed ('0.0.0.0', 0)]
```
- Some miners are not responding (IP 0.0.0.0:0)
- This suggests miners may not be properly registered or running

### 2. **Empty Miner Index**
```
Returning compressed miner index of 0 bytes across 0 buckets
```
- Some miners have no data to provide
- This could be due to:
  - Miners not scraping data yet
  - S3 upload issues
  - Database problems

## Recommended Action Plan

1. **Immediate Fix**: Implement Option 1 (validator auto-configuration)
2. **Verify S3 URLs**: Test both testnet and mainnet S3 auth endpoints
3. **Check Miner Status**: Investigate why some miners show 0.0.0.0:0
4. **Monitor Data Flow**: Ensure miners are successfully uploading to S3
5. **Update Documentation**: Clarify S3 URL configuration requirements

## Files to Modify

1. **`neurons/validator.py`**: Add S3 URL auto-configuration logic
2. **`neurons/config.py`**: Consider updating default S3 URL or adding validation
3. **Documentation**: Update setup guides to clarify S3 URL requirements

This analysis confirms your assumption that validators are trying to start but cannot access miner S3 data due to configuration issues, not just missing data.
